Workbook
Name Slicer_Discount__category: #N/A
Name Slicer_Rating_category: #N/A

Sheet ORIGINAL DATA
A1: Product | B1: Current price | C1: old price | D1: Discount | E1: Review | F1: Ratingd
A2: 115 Piece Set Of Multifunctional Precision Screwdrivers | B2: KSh 950 | C2: KSh 1,525 | D2: 0.38 | E2: -2 | F2: 4.5 out of 5
A3: Metal Decorative Hooks Key Hangers Entryway Wall Hooks Towel Hooks - Home | B3: KSh 527 | C3: KSh 999 | D3: 0.47 | E3: -14 | F3: 4.1 out of 5
A4: Portable Mini Cordless Car Vacuum Cleaner - Blue | B4: KSh 2,199 | C4: KSh 2,923 | D4: 0.25 | E4: -24 | F4: 4.6 out of 5
A5: Weighing Scale Digital Bathroom Body Fat Scale USB-Black | B5: KSh 1,580 | C5: KSh 2,499 | D5: 0.37 | E5: -7 | F5: 4.7 out of 5
A6: Portable Home Small Air Humidifier 3-Speed Fan - Green | B6: KSh 1,740 | C6: KSh 2,356 | D6: 0.26 | E6: -5 | F6: 4.8 out of 5
A7: 220V 60W Electric Soldering Iron Kits With Tools, Tips, And Multimeter | B7: KSh 2,999 | C7: KSh 3,290 | D7: 0.09 | E7: -15 | F7: 4 out of 5
A8: 137 Pieces Cake Decorating Tool Set Baking Supplies | B8: KSh 2,319 | C8: KSh 3,032 | D8: 0.24 | E8: -55 | F8: 4.6 out of 5
A9: Desk Foldable Fan Adjustable Fan Strong Wind 3 Gear Usb | B9: KSh 988 | C9: KSh 1,580 | D9: 0.37 | E9: -2 | F9: 4 out of 5
A10: LASA FOLDING TABLE SERVING STAND | B10: KSh 1,274 | C10: KSh 2,800 | D10: 0.55 | E10: -5 | F10: 4.8 out of 5
A11: 13 In 1 Home Repair Tools Box Kit Set | B11: KSh 1,600 | C11: KSh 2,929 | D11: 0.45 | E11: -5 | F11: 3.8 out of 5
A12: Genebre 115 In 1 Screwdriver Repairing Tool Set For IPhone Cellphone Hand Tool | B12: KSh 799 | C12: KSh 999 | D12: 0.2 | E12: -12 | F12: 4.1 out of 5
A13: 100 Pcs Crochet Hook Tool Set Knitting Hook Set With Box | B13: KSh 990 | C13: KSh 1,500 | D13: 0.34 | E13: -39 | F13: 4.7 out of 5
... A22: 3PCS Single Head Knitting Crochet Sweater Needle Set | B22: KSh 38 | C22: KSh 80 | D22: 0.53 | E22: -13 | F22: 3.3 out of 5
A23: 4pcs Bathroom/Kitchen Towel Rack,Roll Paper Holder,Towel Bars,Hook | B23: KSh 1,860 | C23: KSh 3,220 | D23: 0.42
A24: LED Romantic Spaceship Starry Sky Projector,Children's Bedroom Night Light-Blue | B24: KSh 880 | C24: KSh 1,350 | D24: 0.35 | E24: -6 | F24: 4 out of 5
A25: Foldable Overbed Table/Desk | B25: KSh 1,650 | C25: KSh 2,150 | D25: 0.23 | E25: -14 | F25: 4.4 out of 5
A26: LASA 3 Tier Bamboo Shoe Bench Storage Shelf | B26: KSh 2,048 | C26: KSh 4,500 | D26: 0.54 | E26: -7 | F26: 4.3 out of 5
A27: Electronic Digital Display Vernier Caliper | B27: KSh 420 | C27: KSh 647 | D27: 0.35 | E27: -49 | F27: 4.6 out of 5
A28: Portable Wardrobe Nonwoven With 3 Hanging Rods And 6 Storage Shelves | B28: KSh 2,880 | C28: KSh 3,520 | D28: 0.18 | E28: -12 | F28: 3.8 out of 5
A29: 12 Litre Black Insulated Lunch Box | B29: KSh 1,350 | C29: KSh 1,990 | D29: 0.32 | E29: -13 | F29: 3.8 out of 5
A30: 52 Pieces Cake Decorating Tool Set Gift Kit Baking Supplies | B30: KSh 1,758 | C30: KSh 2,499 | D30: 0.3 | E30: -20 | F30: 4.1 out of 5
A31: MultiFunctional Storage Rack Multi-layer Bookshelf | B31: KSh 2,200 | C31: KSh 4,080 | D31: 0.46
A32: Exfoliate And Exfoliate Face Towel - Black | B32: KSh 185 | C32: KSh 382 | D32: 0.52 | E32: -9 | F32: 4.3 out of 5
A33: 12 Litre Insulated Lunch Box Grey | B33: KSh 980 | C33: KSh 1,490 | D33: 0.34 | E33: -12 | F33: 4.7 out of 5
A34: LED Eye Protection Desk Lamp , Study, Reading, USB Fan - Double Pen Holder | B34: KSh 1,820 | C34: KSh 3,490 | D34: 0.48 | E34: -9 | F34: 4.3 out of 5
A35: 53Pcs/Set Yarn Knitting Crochet Hooks With Bag - Fortune Cat | B35: KSh 1,940 | C35: KSh 2,650 | D35: 0.27 | E35: -20 | F35: 4.7 out of 5
A36: 53 Pieces/Set Yarn Knitting Crochet Hooks With Bag - Pansies | B36: KSh 1,980 | C36: KSh 2,699 | D36: 0.27 | E36: -32 | F36: 4.5 out of 5
A37: DIY File Folder, Office Drawer File Holder, Pen Holder, Desktop Storage Rack | B37: KSh 1,620 | C37: KSh 2,690 | D37: 0.4 | E37: -1 | F37: 5 out of 5
A38: Classic Black Cat Cotton Hemp Pillow Case For Home Car | B38: KSh 171 | C38: KSh 360 | D38: 0.53 | E38: -2 | F38: 5 out of 5
A39: Punch-free Great Load Bearing Bathroom Storage Rack Wall Shelf-White | B39: KSh 389 | C39: KSh 656 | D39: 0.41 | E39: -36 | F39: 4.3 out of 5
A40: 1/2/3 Seater Elastic Sofa Cover,Living Room/Home Decor Chair Cover-Grey | B40: KSh 1,620 - KSh 1,980 | C40: KSh 2,200 - KSh 3,200 | D40: 0.38 | E40: -2 | F40: 4.5 out of 5
A41: LASA Stainless Steel Double Wall Mount Soap Dispenser - 500ml | B41: KSh 2,750 | C41: KSh 4,471 | D41: 0.38
A42: 4M Float Switch Water Level Controller -Water Tank | B42: KSh 475 | C42: KSh 931 | D42: 0.49
A43: Modern Sofa Throw Pillow Cover-45x45cm-Blue&Red | B43: KSh 238 | C43: KSh 476 | D43: 0.5
A44: Balloon Insert, Birthday Party Balloon Set, PU Leather | B44: KSh 610 | C44: KSh 1,060 | D44: 0.42
A45: Balloon Insert, Birthday Party Balloon Set, PU Leather | B45: KSh 610 | C45: KSh 1,060 | D45: 0.42
A46: Shower Cap Wide Elastic Band Cover Reusable Bashroom Cap | B46: KSh 2,132 | C46: KSh 2,169 | D46: 0.02
A47: Christmas Elk Fence Yard Lawn Decorations Cute For Holidays | B47: KSh 999 | C47: KSh 2,000 | D47: 0.5
A48: 60W Hot Melt Glue Sprayer - Efficient And Stable Glue Dispensing | B48: KSh 1,190 | C48: KSh 1,785 | D48: 0.33
...

Sheet WORKING
A1: Product | B1: Current price | C1: old price | D1: Discount amnt | E1: Discount % | F1: No of Review | G1: Ratings | H1: Rating category | I1: Discount category
A2: DIY File Folder, Office Drawer File Holder, Pen Holder, Desktop Storage Rack | B2: 1620 | C2: 2690 | D2: =C2-B2 -> 1070 | E2: 0.4 | F2: 1 | G2: 5 | H2: =IF(F2<3,"poor",IF(F2<=4.4,"Average",IF(F2>=4.5,"Excellent"))) -> poor | I2: =IF(E2<20%,"Low Discount",IF(E2<=40%,"Medium Discount",IF(E2>40%,"High Discount"))) -> Medium Discount
A3: Memory Foam Neck Pillow Cover, With Pillow Core - 50*30cm | B3: 1189 | C3: 2199 | D3: =C3-B3 -> 1010 | E3: 0.46 | F3: 1 | G3: 3 | H3: =IF(F3<3,"poor",IF(F3<=4.4,"Average",IF(F3>=4.5,"Excellent"))) -> poor | I3: =IF(E3<20%,"Low Discount",IF(E3<=40%,"Medium Discount",IF(E3>40%,"High Discount"))) -> High Discount
A4: Bedroom Simple Floor Hanging Clothes Rack Single Pole Hat Rack - White | B4: 979 | C4: 1920 | D4: =C4-B4 -> 941 | E4: 0.49 | F4: 1 | G4: 5 | H4: =IF(F4<3,"poor",IF(F4<=4.4,"Average",IF(F4>=4.5,"Excellent"))) -> poor | I4: =IF(E4<20%,"Low Discount",IF(E4<=40%,"Medium Discount",IF(E4>40%,"High Discount"))) -> High Discount
A5: Household Pineapple Peeler Peeler | B5: 330 | C5: 647 | D5: =C5-B5 -> 317 | E5: 0.49 | F5: 1 | G5: 4 | H5: =IF(F5<3,"poor",IF(F5<=4.4,"Average",IF(F5>=4.5,"Excellent"))) -> poor | I5: =IF(E5<20%,"Low Discount",IF(E5<=40%,"Medium Discount",IF(E5>40%,"High Discount"))) -> High Discount
A6: Konka Healty Electric Kettle, 24-hour Heat Preservation,1.5L,800W, White | B6: 3640 | C6: 4588 | D6: =C6-B6 -> 948 | E6: 0.21 | F6: 1 | G6: 5 | H6: =IF(F6<3,"poor",IF(F6<=4.4,"Average",IF(F6>=4.5,"Excellent"))) -> poor | I6: =IF(E6<20%,"Low Discount",IF(E6<=40%,"Medium Discount",IF(E6>40%,"High Discount"))) -> Medium Discount
A7: Wall-mounted Sticker Punch-free Plug Fixer | B7: 450 | C7: 900 | D7: =C7-B7 -> 450 | E7: 0.5 | F7: 1 | G7: 2 | H7: =IF(F7<3,"poor",IF(F7<=4.4,"Average",IF(F7>=4.5,"Excellent"))) -> poor | I7: =IF(E7<20%,"Low Discount",IF(E7<=40%,"Medium Discount",IF(E7>40%,"High Discount"))) -> High Discount
A8: 115 Piece Set Of Multifunctional Precision Screwdrivers | B8: 950 | C8: 1525 | D8: =C8-B8 -> 575 | E8: 0.38 | F8: 2 | G8: 4.5 | H8: =IF(F8<3,"poor",IF(F8<=4.4,"Average",IF(F8>=4.5,"Excellent"))) -> poor | I8: =IF(E8<20%,"Low Discount",IF(E8<=40%,"Medium Discount",IF(E8>40%,"High Discount"))) -> Medium Discount
A9: Desk Foldable Fan Adjustable Fan Strong Wind 3 Gear Usb | B9: 988 | C9: 1580 | D9: =C9-B9 -> 592 | E9: 0.37 | F9: 2 | G9: 4 | H9: =IF(F9<3,"poor",IF(F9<=4.4,"Average",IF(F9>=4.5,"Excellent"))) -> poor | I9: =IF(E9<20%,"Low Discount",IF(E9<=40%,"Medium Discount",IF(E9>40%,"High Discount"))) -> Medium Discount
A10: Anti-Skid Absorbent Insulation Coaster For Home Office | B10: 332 | C10: 684 | D10: =C10-B10 -> 352 | E10: 0.51 | F10: 2 | G10: 5 | H10: =IF(F10<3,"poor",IF(F10<=4.4,"Average",IF(F10>=4.5,"Excellent"))) -> poor | I10: =IF(E10<20%,"Low Discount",IF(E10<=40%,"Medium Discount",IF(E10>40%,"High Discount"))) -> High Discount
A11: Peacock Throw Pillow Cushion Case For Home Car | B11: 195 | C11: 360 | D11: =C11-B11 -> 165 | E11: 0.46 | F11: 2 | G11: 5 | H11: =IF(F11<3,"poor",IF(F11<=4.4,"Average",IF(F11>=4.5,"Excellent"))) -> poor | I11: =IF(E11<20%,"Low Discount",IF(E11<=40%,"Medium Discount",IF(E11>40%,"High Discount"))) -> High Discount
A12: Classic Black Cat Cotton Hemp Pillow Case For Home Car | B12: 171 | C12: 360 | D12: =C12-B12 -> 189 | E12: 0.53 | F12: 2 | G12: 5 | H12: =IF(F12<3,"poor",IF(F12<=4.4,"Average",IF(F12>=4.5,"Excellent"))) -> poor | I12: =IF(E12<20%,"Low Discount",IF(E12<=40%,"Medium Discount",IF(E12>40%,"High Discount"))) -> High Discount
A13: 1/2/3 Seater Elastic Sofa Cover,Living Room/Home Decor Chair Cover-Grey | B13: 1800 | C13: 2700 | D13: =C13-B13 -> 900 | E13: 0.33 | F13: 2 | G13: 4.5 | H13: =IF(F13<3,"poor",IF(F13<=4.4,"Average",IF(F13>=4.5,"Excellent"))) -> poor | I13: =IF(E13<20%,"Low Discount",IF(E13<=40%,"Medium Discount",IF(E13>40%,"High Discount"))) -> Medium Discount
... A110: Black Simple Water Cup Wine Coaster Anti Slip Absorbent | B110: 169 | C110: 320 | D110: =C110-B110 -> 151 | E110: 0.47 | F110: 0 | G110: 0 | H110: =IF(F110<3,"poor",IF(F110<=4.4,"Average",IF(F110>=4.5,"Excellent"))) -> poor | I110: =IF(E110<20%,"Low Discount",IF(E110<=40%,"Medium Discount",IF(E110>40%,"High Discount"))) -> High Discount

Sheet Sheet2
A3: Row Labels | B3: Sum of No of Review
A4: 0.01 | B4: 0
A5: 0.02 | B5: 0
A6: 0.03 | B6: 0
A7: 0.04 | B7: 0
A8: 0.08 | B8: 0
A9: 0.09 | B9: 15
A10: 0.11 | B10: 0
A11: 0.13 | B11: 6
A12: 0.14 | B12: 0
A13: 0.18 | B13: 12
A14: 0.19 | B14: 5
A15: 0.2 | B15: 12
... A49: 0.64 | B49: 0
A50: Grand Total | B50: 723

Sheet Descriptive Analysis
A1: Descriptive Analysis
A2: • What is the average current price, old price, discount percentage, and rating?
A3: • Which product is the most expensive and which is the least expensive?
A4: • What is the average rating and discount by discount category?
A5: • How are products distributed across rating categories?
B7: current price | C7: Old Price | D7: Discount % | E7: Rating
A8: Average | B8: =AVERAGE(WORKING!B2:B110) -> 1208.2569 | C8: =AVERAGE(WORKING!C2:C110) -> 1837.7523 | D8: =AVERAGE(WORKING!E2:E110) -> 0.3633945 | E8: =AVERAGE(WORKING!G2:G110) -> 2.033945
A9: most expensive product | B9: =MAX(WORKING!B2:B110) -> 3750
A10: Least expensive product | B10: =MIN(WORKING!B2:B110) -> 38
A11: What is the average rating and discount by discount category? Hign disc | B11: =AVERAGEIF(WORKING!I2:I110, "High Discount", WORKING!G2:G110) -> 1.8372881
A12: Low discount | B12: =AVERAGEIF(WORKING!I2:I111,"Low Discount",WORKING!G2:G111) -> 0.82777778
A13: High Discount by rating | B13: =AVERAGEIF(WORKING!I2:I112,"High Discount",WORKING!F2:F112) -> 5.6610169
A14: Low Discount by rating | B14: =AVERAGEIF(WORKING!I2:I113,"Low Discount",WORKING!F2:F113) -> 2.1111111
A15: • How are products distributed across rating categories?
A16: Poor | B16: =COUNTIF(WORKING!H2:H110,"POOR") -> 64
A17: Average | B17: =COUNTIF(WORKING!H2:H111,"Average") -> 1
A18: Excellent | B18: =COUNTIF(WORKING!H2:H112,"Excellent") -> 44
A21: Trend and Relationship Analysis
A22: • Analyze the relationship between discount percentage and number of reviews
A23: There is a very weak positive correlation checking from the graph. In this dataset, offering a higher discount does not automatically result in a higher number of reviews.
A25: • Analyze the relationship between rating and number of reviews
A26: There is a noticeable link between the two. Generally, products that have higher ratings also tend to have a higher number of reviews. leading to more customers buying them and subsequently leave their own reviews.
A27: • Determine whether higher discounts lead to increased customer engagement
A28: The relationship is non-linear. While products with very low discounts have the lowest engagement, the highest engagement actually occurs at Medium Discount (typically between 20% and 40%) rather than High Discount
A29: • Determine whether higher-rated products tend to have more reviews
A30: Based on the dataset, higher-rated products do tend to have more reviews. There is a clear relationship where products in the "Excellent" category significantly outperform those in the "Poor" category in terms of engagement.
A33: Product Performance Analysis
A34: • Identify the top 10 products with the highest discounts
A35: Product | B35: Discount amnt
A36: 5-PCS Stainless Steel Cooking Pot Set With Steamed Slices | B36: 2585
A37: LASA 3 Tier Bamboo Shoe Bench Storage Shelf | B37: 2452
A38: 32PCS Portable Cordless Drill Set With Cyclic Battery Drive -26 Variable Speed | B38: 2393
A39: LASA Aluminum Folding Truck Hand Cart - 68kg Max | B39: 1946
A40: MultiFunctional Storage Rack Multi-layer Bookshelf | B40: 1880
A41: LASA Stainless Steel Double Wall Mount Soap Dispenser - 500ml | B41: 1721
A42: LED Eye Protection Desk Lamp , Study, Reading, USB Fan - Double Pen Holder | B42: 1670
A43: LASA FOLDING TABLE SERVING STAND | B43: 1526
A44: Electric LED UV Mosquito Killer Lamp, Outdoor/Indoor Fly Killer Trap Light -USB | B44: 1418
A45: 4pcs Bathroom/Kitchen Towel Rack,Roll Paper Holder,Towel Bars,Hook | B45: 1360
A47: Identify the top 10 products with the most reviews
...

Sheet Sheet4
A3: Ratings | B3: Sum of No of Review
A4: 0 | B4: 0
A5: 2 | B5: 1
A6: 2.1 | B6: 20
A7: 2.2 | B7: 12
A8: 2.3 | B8: 13
A9: 2.5 | B9: 6
A10: 2.6 | B10: 17
A11: 2.7 | B11: 15
A12: 2.8 | B12: 69
A13: 2.9 | B13: 16
A14: 3 | B14: 26
A15: 3.3 | B15: 13
... A26: 5 | B26: 12

Sheet Sheet6
A1: Ratings | B1: (Multiple Items)
A3: Row Labels | B3: Product of Ratings
A4: Wall-mounted Sticker Punch-free Plug Fixer | B4: 2
A5: Electric LED UV Mosquito Killer Lamp, Outdoor/Indoor Fly Killer Trap Light -USB | B5: 2.1
A6: Artificial Potted Flowers Room Decorative Flowers (2 Pieces) | B6: 2.2
A7: 7-piece Set Of Storage Bags, Travel Storage Bags, Shoe Bags | B7: 2.2
A8: 5-PCS Stainless Steel Cooking Pot Set With Steamed Slices | B8: 2.1
A9: 5 Pieces/set Of Stainless Steel Induction Cooker Pots | B9: 2.5
A10: Grand Total | B10: 106.722

Sheet Sheet8
A3: Row Labels | B3: Sum of Ratings
A4: 1/2/3 Seater Elastic Sofa Cover,Living Room/Home Decor Chair Cover-Grey | B4: 4.5
A5: 100 Pcs Crochet Hook Tool Set Knitting Hook Set With Box | B5: 4.7
A6: 115 Piece Set Of Multifunctional Precision Screwdrivers | B6: 4.5
A7: 12 Litre Black Insulated Lunch Box | B7: 3.8
A8: 12 Litre Insulated Lunch Box Grey | B8: 4.7
A9: 120W Cordless Vacuum Cleaners Handheld Electric Vacuum Cleaner | B9: 2.8
A10: 12V 19500rpm Handheld Electric Angle Grinder Tool - UK - Yellow/Black | B10: 0
A11: 13 In 1 Home Repair Tools Box Kit Set | B11: 3.8
A12: 137 Pieces Cake Decorating Tool Set Baking Supplies | B12: 4.6
A13: 1PC Refrigerator Food Seal Pocket Fridge Bags | B13: 0
A14: 2 Pairs Cowhide Split Leather Work Gloves.32â„‰ Or Above Welding Gloves | B14: 0
A15: 220V 60W Electric Soldering Iron Kits With Tools, Tips, And Multimeter | B15: 4
... A113: Grand Total | B113: 221.7

Sheet Sheet7
A3: Row Labels | B3: Sum of Ratings
A4: High Discount | B4: 108.4
A5: Low Discount | B5: 14.9
A6: Medium Discount | B6: 98.4
A7: Grand Total | B7: 221.7
A18: Row Labels | B18: Sum of No of Review
A19: Average | B19: 3
A20: Excellent | B20: 702
A21: poor | B21: 18
A22: Grand Total | B22: 723
A31: Row Labels | B31: Count of Product
A32: Average | B32: 1
A33: Excellent | B33: 44
A34: poor | B34: 64
A35: Grand Total | B35: 109
A47: Row Labels | B47: Count of Product
A48: High Discount | B48: 59
A49: Low Discount | B49: 18
A50: Medium Discount | B50: 32
A51: Grand Total | B51: 109

Sheet WORKING (2)
A1: Product | B1: Current price | C1: old price | D1: Discount amnt | E1: Discount % | F1: No of Review | G1: Ratings | H1: Rating category | I1: Discount category
A2: 5-PCS Stainless Steel Cooking Pot Set With Steamed Slices | B2: 2115 | C2: 4700 | D2: =C2-B2 -> 2585 | E2: 0.55 | F2: 13 | G2: 2.1 | H2: =IF(F2<3,"poor",IF(F2<=4.4,"Average",IF(F2>=4.5,"Excellent"))) -> Excellent | I2: =IF(E2<20%,"Low Discount",IF(E2<=40%,"Medium Discount",IF(E2>40%,"High Discount"))) -> High Discount
A3: LASA 3 Tier Bamboo Shoe Bench Storage Shelf | B3: 2048 | C3: 4500 | D3: =C3-B3 -> 2452 | E3: 0.54 | F3: 7 | G3: 4.3 | H3: =IF(F3<3,"poor",IF(F3<=4.4,"Average",IF(F3>=4.5,"Excellent"))) -> Excellent | I3: =IF(E3<20%,"Low Discount",IF(E3<=40%,"Medium Discount",IF(E3>40%,"High Discount"))) -> High Discount
A4: 32PCS Portable Cordless Drill Set With Cyclic Battery Drive -26 Variable Speed | B4: 3750 | C4: 6143 | D4: =C4-B4 -> 2393 | E4: 0.39 | F4: 5 | G4: 3 | H4: =IF(F4<3,"poor",IF(F4<=4.4,"Average",IF(F4>=4.5,"Excellent"))) -> Excellent | I4: =IF(E4<20%,"Low Discount",IF(E4<=40%,"Medium Discount",IF(E4>40%,"High Discount"))) -> Medium Discount
A5: LASA Aluminum Folding Truck Hand Cart - 68kg Max | B5: 2025 | C5: 3971 | D5: =C5-B5 -> 1946 | E5: 0.49 | F5: 3 | G5: 5 | H5: =IF(F5<3,"poor",IF(F5<=4.4,"Average",IF(F5>=4.5,"Excellent"))) -> Average | I5: =IF(E5<20%,"Low Discount",IF(E5<=40%,"Medium Discount",IF(E5>40%,"High Discount"))) -> High Discount
A6: MultiFunctional Storage Rack Multi-layer Bookshelf | B6: 2200 | C6: 4080 | D6: =C6-B6 -> 1880 | E6: 0.46 | F6: 0 | G6: 0 | H6: =IF(F6<3,"poor",IF(F6<=4.4,"Average",IF(F6>=4.5,"Excellent"))) -> poor | I6: =IF(E6<20%,"Low Discount",IF(E6<=40%,"Medium Discount",IF(E6>40%,"High Discount"))) -> High Discount
A7: LASA Stainless Steel Double Wall Mount Soap Dispenser - 500ml | B7: 2750 | C7: 4471 | D7: =C7-B7 -> 1721 | E7: 0.38 | F7: 0 | G7: 0 | H7: =IF(F7<3,"poor",IF(F7<=4.4,"Average",IF(F7>=4.5,"Excellent"))) -> poor | I7: =IF(E7<20%,"Low Discount",IF(E7<=40%,"Medium Discount",IF(E7>40%,"High Discount"))) -> Medium Discount
A8: LED Eye Protection Desk Lamp , Study, Reading, USB Fan - Double Pen Holder | B8: 1820 | C8: 3490 | D8: =C8-B8 -> 1670 | E8: 0.48 | F8: 9 | G8: 4.3 | H8: =IF(F8<3,"poor",IF(F8<=4.4,"Average",IF(F8>=4.5,"Excellent"))) -> Excellent | I8: =IF(E8<20%,"Low Discount",IF(E8<=40%,"Medium Discount",IF(E8>40%,"High Discount"))) -> High Discount
A9: LASA FOLDING TABLE SERVING STAND | B9: 1274 | C9: 2800 | D9: =C9-B9 -> 1526 | E9: 0.55 | F9: 5 | G9: 4.8 | H9: =IF(F9<3,"poor",IF(F9<=4.4,"Average",IF(F9>=4.5,"Excellent"))) -> Excellent | I9: =IF(E9<20%,"Low Discount",IF(E9<=40%,"Medium Discount",IF(E9>40%,"High Discount"))) -> High Discount
A10: Electric LED UV Mosquito Killer Lamp, Outdoor/Indoor Fly Killer Trap Light -USB | B10: 1570 | C10: 2988 | D10: =C10-B10 -> 1418 | E10: 0.47 | F10: 7 | G10: 2.1 | H10: =IF(F10<3,"poor",IF(F10<=4.4,"Average",IF(F10>=4.5,"Excellent"))) -> Excellent | I10: =IF(E10<20%,"Low Discount",IF(E10<=40%,"Medium Discount",IF(E10>40%,"High Discount"))) -> High Discount
A11: 4pcs Bathroom/Kitchen Towel Rack,Roll Paper Holder,Towel Bars,Hook | B11: 1860 | C11: 3220 | D11: =C11-B11 -> 1360 | E11: 0.42 | F11: 0 | G11: 0 | H11: =IF(F11<3,"poor",IF(F11<=4.4,"Average",IF(F11>=4.5,"Excellent"))) -> poor | I11: =IF(E11<20%,"Low Discount",IF(E11<=40%,"Medium Discount",IF(E11>40%,"High Discount"))) -> High Discount
A12: 13 In 1 Home Repair Tools Box Kit Set | B12: 1600 | C12: 2929 | D12: =C12-B12 -> 1329 | E12: 0.45 | F12: 5 | G12: 3.8 | H12: =IF(F12<3,"poor",IF(F12<=4.4,"Average",IF(F12>=4.5,"Excellent"))) -> Excellent | I12: =IF(E12<20%,"Low Discount",IF(E12<=40%,"Medium Discount",IF(E12>40%,"High Discount"))) -> High Discount
A13: Portable Wine Table With Folding Round Table | B13: 1300 | C13: 2500 | D13: =C13-B13 -> 1200 | E13: 0.48 | F13: 0 | G13: 0 | H13: =IF(F13<3,"poor",IF(F13<=4.4,"Average",IF(F13>=4.5,"Excellent"))) -> poor | I13: =IF(E13<20%,"Low Discount",IF(E13<=40%,"Medium Discount",IF(E13>40%,"High Discount"))) -> High Discount
... A110: 24 Grid Wall-mounted Sundries Organiser Fabric Closet Bag Storage Rack | B110: 1875 | C110: 1899 | D110: =C110-B110 -> 24 | E110: 0.01 | F110: 0 | G110: 0 | H110: =IF(F110<3,"poor",IF(F110<=4.4,"Average",IF(F110>=4.5,"Excellent"))) -> poor | I110: =IF(E110<20%,"Low Discount",IF(E110<=40%,"Medium Discount",IF(E110>40%,"High Discount"))) -> Low Discount

Sheet DASHBOARD
